<?xml version="1.0"?>
<robot xmlns:xacro="http://www.ros.org/wiki/xacro" name="cyton_gamma_300">

	<xacro:include filename="$(find cyton_gamma_300_description)/urdf/cyton_gamma_300.gazebo" />-
	<xacro:include filename="$(find cyton_gamma_300_description)/urdf/materials.xacro" />

	<link name="world"/>

  	<joint name="fixed" type="fixed">
    	<parent link="world"/>
    	<child link="base_footprint"/>
  	</joint>

  	<link name="base_footprint">
        <visual>
            <origin xyz="0 0 0" rpy="0 0 0"/>
            <geometry>
                <sphere radius="0.001" />
            </geometry>
        </visual>
    </link>

    <joint name="base_joint" type="fixed">
        <parent link="base_footprint" />
        <child link="base_link" />
       <origin xyz="0.0 0.0 0.0" rpy="0 0 0" />
    </joint>

    <!-- Base of robot here -->
    <link name="base_link">
        <inertial>
            <origin rpy="0 0 0" xyz="-0.005448 0.010279 0.024284"/>
            <inertia ixx="0.007305" ixy="-0.000051" ixz="-0.000056" iyy="0.006579" iyz="0.000372" izz="0.010933" />
            <mass value="0.901"/>
        </inertial>
        <visual>
            <origin xyz="0 0 0" rpy="0 0 0"/>
            <geometry>
                <mesh filename="package://cyton_gamma_300_description/meshes/gamma_base.dae"/>
            </geometry>
            <material name="black"/>
        </visual>
        <collision>
            <origin xyz="0 0 0" rpy="0 0 0"/>
            <geometry>
                <mesh filename="package://cyton_gamma_300_description/meshes/gamma_base.stl"/>
            </geometry>
        </collision>
    </link>

    <!-- First motor located here -->
    <joint name="shoulder_roll_joint" type="revolute">
        <parent link="base_link" />
        <child link="shoulder_roll" />
        <origin xyz="0 0 0.05315" rpy="0 0 1.2" />
        <limit lower="-2.618" upper="2.618" effort="100.0" velocity="1.0" />
        <axis xyz="0 0 1" />
    </joint>

    <link name="shoulder_roll">
        <inertial>
            <origin rpy="0 0 0" xyz="0.000027 0.026919 -0.000272"/>
            <mass value="0.286"/>
            <inertia ixx="0.000817" ixy="0.000002" ixz="0.000000" iyy="0.000352" iyz="-0.000003" izz="0.000866"/>
        </inertial>
        <visual>
            <origin xyz="0 0 0" rpy="1.5708 0 3.14159"/>
            <geometry>
                <mesh filename="package://cyton_gamma_300_description/meshes/Shoulder_Roll.dae"/>
            </geometry>
            <material name="black"/>
        </visual>
        <collision>
            <origin xyz="0 0 0" rpy="0 0 -1.5708"/>
            <geometry>
                <mesh filename="package://cyton_gamma_300_description/meshes/Shoulder_Roll.stl"/>
            </geometry>
        </collision>
    </link>

    <!-- Second motor located here -->
    <joint name="shoulder_pitch_joint" type="revolute">
        <parent link="shoulder_roll" />
        <child link="shoulder_pitch" />
        <origin xyz="0 0 0.063" rpy="1.2 0 0" />
        <limit lower="-1.8326" upper="1.8326" effort="100.0" velocity="1.0" />
        <axis xyz="1 0 0" />
    </joint>

    <link name="shoulder_pitch">
        <inertial>
            <origin rpy="0 0 0" xyz="-0.057818 -0.000005 -0.020753"/>
            <mass value="0.162"/>
            <inertia ixx="0.000177" ixy="0.000000" ixz="0.000016" iyy="0.000419" iyz="-0.000000" izz="0.000347"/>
        </inertial>
        <visual>
            <origin xyz="0.028 0 0" rpy="0 1.5708 0" />
            <geometry>
                <mesh filename="package://cyton_gamma_300_description/meshes/Shoulder_Pitch.dae"/>
            </geometry>
            <material name="black"/>
        </visual>
        <collision>
            <origin xyz="0.028 0 0" rpy="0 0 -1.5708" />
            <geometry>
                <mesh filename="package://cyton_gamma_300_description/meshes/Shoulder_Pitch.stl"/>
            </geometry>
        </collision>
    </link>

    <!-- Third motor located here -->
    <joint name="elbow_roll_joint" type="revolute">
        <parent link="shoulder_pitch" />
        <child link="elbow_roll" />
        <origin xyz="0 0 0.089" rpy="0 0 1.2" />
        <limit lower="-1.8326" upper="1.8326" effort="100.0" velocity="1.0" />
        <axis xyz="0 0 1" />
    </joint>

    <link name="elbow_roll">
        <inertial>
            <origin rpy="0 0 0" xyz="0.000064 -0.000046 0.032285"/>
            <mass value="0.124"/>
            <inertia ixx="0.000192" ixy="0.000017" ixz="0.000001" iyy="0.000192" iyz="-0.000001" izz="0.000090"/>
        </inertial>
        <visual>
            <origin xyz="0 0 0" rpy="0 0 3.92699" />
            <geometry>
                <mesh filename="package://cyton_gamma_300_description/meshes/Elbow_Roll.dae"/>
            </geometry>
            <material name="black"/>
        </visual>
        <collision>
            <origin xyz="0 0 0" rpy="0 0 1.57" />
            <geometry>
                <mesh filename="package://cyton_gamma_300_description/meshes/Elbow_Roll.stl"/>
            </geometry>
        </collision>
    </link>

    <!-- Fourth motor located here -->
    <joint name="elbow_pitch_joint" type="revolute">
        <parent link="elbow_roll" />
        <child link="elbow_pitch" />
        <origin xyz="0 0 0.052" rpy="1.2 0 0" />
        <limit lower="-1.8326" upper="1.8326" effort="100.0" velocity="1.0" />
        <axis xyz="1 0 0" />
    </joint>

    <link name="elbow_pitch">
        <inertial>
            <origin rpy="0 0 0" xyz="0.000104 0.055008 -0.026105"/>
            <mass value="0.107"/>
            <inertia ixx="0.000176" ixy="0.000001" ixz="0.000000" iyy="0.000075" iyz="0.000003" izz="0.000181"/>
        </inertial>
        <visual>
        <!-- Not sure if this is the correct orientation. -->
            <origin xyz="0.027 0 0" rpy="1.5708 0 1.5708" />
            <geometry>
                <mesh filename="package://cyton_gamma_300_description/meshes/Elbow_Pitch.dae"/>
            </geometry>
            <material name="black"/>
        </visual>
        <collision>
            <origin xyz="0.027 0 0" rpy="0 0 1.57" />
            <geometry>
                <mesh filename="package://cyton_gamma_300_description/meshes/Elbow_Pitch.stl"/>
            </geometry>
        </collision>
    </link>

    <!-- Fifth motor located here -->
    <joint name="elbow_yaw_joint" type="revolute">
        <parent link="elbow_pitch" />
        <child link="elbow_yaw" />
        <origin xyz="0 0 0.072" rpy="0 -1.2 0" />
        <limit lower="-1.8326" upper="1.8326" effort="100.0" velocity="1.0" />
        <axis xyz="0 -1 0" />
    </joint>

    <link name="elbow_yaw">
        <inertial>
            <origin rpy="0 0 0" xyz="0.000103 0.054796 -0.001090"/>
            <mass value="0.107"/>
            <inertia ixx="0.000181" ixy="0.000001" ixz="0.000000" iyy="0.000076" iyz="0.000001" izz="0.000186"/>
        </inertial>
        <visual>
            <origin xyz="0 0 0" rpy="1.5708 0 0" />
            <geometry>
                <mesh filename="package://cyton_gamma_300_description/meshes/Elbow_Yaw.dae"/>
            </geometry>
            <material name="black"/>
        </visual>
        <collision>
            <origin xyz="0 0 0" rpy="0 0 1.57" />
            <geometry>
                <mesh filename="package://cyton_gamma_300_description/meshes/Elbow_Yaw.stl"/>
            </geometry>
        </collision>
    </link>

    <!-- Sixth motor located here -->
    <joint name="wrist_pitch_joint" type="revolute">
        <parent link="elbow_yaw" />
        <child link="wrist_pitch" />
        <origin rpy="1.5708 0 1.5708" xyz="0.0263 0 0.070"/>
        <limit lower="-1.8326" upper="1.8326" effort="100.0" velocity="1.0" />
        <axis xyz="0 0 1"/>
    </joint>

    <link name="wrist_pitch">
        <inertial>
            <origin rpy="0 0 0" xyz="0.000000 0.017892 -0.029854"/>
            <mass value="0.015"/>
            <inertia ixx="2.64e-005" ixy="-2.04e-013" ixz="3.74e-013" iyy="1.91e-005" iyz="8.46e-006" izz="8.91e-006"/>
            <!--inertia ixx="0.000027" ixy="0.000000" ixz="0.000000" iyy="0.000000" iyz="0.000002" izz="0.000000"/-->
        </inertial>
        <visual>
            <origin rpy="0 0 0" xyz="0 0 0"/>
            <geometry>
                <mesh filename="package://cyton_gamma_300_description/meshes/Wrist_Pitch.dae"/>
            </geometry>
            <material name="black"/>
        </visual>
        <collision>
            <origin xyz="0 0 0" rpy="1.57 0 3.14" />
            <geometry>
                <mesh filename="package://cyton_gamma_300_description/meshes/Wrist_Pitch.stl"/>
            </geometry>
        </collision>
    </link>

    <!-- Seventh motor located here -->
    <joint name="wrist_roll_joint" type="revolute">
        <parent link="wrist_pitch" />
        <child link="wrist_roll" />
        <origin rpy="4.71 0 3.14" xyz="0 0.05 -0.027"/>
        <limit lower="-2.61799" upper="2.61799" effort="100.0" velocity="1.0" />
        <axis xyz="0 0 1" />
    </joint>

    <link name="wrist_roll">
        <inertial>
            <origin rpy="0 0 0" xyz="-0.000704 -0.001866 -0.010629"/>
            <mass value="0.205"/>
            <inertia ixx="0.000519" ixy="0.000004" ixz="0.000021" iyy="0.000308" iyz="0.000014" izz="0.000346"/>
        </inertial>
        <visual>
            <origin rpy="0 0 0" xyz="0 0 0"/>
            <geometry>
                <mesh filename="package://cyton_gamma_300_description/meshes/Wrist_Roll.dae"/>
            </geometry>
            <material name="black"/>
        </visual>
        <collision>
            <origin xyz="0 0 0" rpy="3.14 0 0" />
            <geometry>
                <mesh filename="package://cyton_gamma_300_description/meshes/Wrist_Roll.stl"/>
            </geometry>
        </collision>
    </link>

    <!-- Eighth motor located here -->
    <joint name="gripper_joint" type="prismatic">
        <parent link="wrist_roll" />
        <child link="gripper_finger1" />
        <origin rpy="3.14 0 1.57" xyz="-0.010 -0.010 -0.043"/>
        <limit lower="-0.008" upper="0.008" effort="100.0" velocity="1.0" />
        <axis xyz="1 0 0" />
    </joint>

    <link name="gripper_finger1">
        <inertial>
            <origin rpy="0 0 0" xyz="-0.008938 0.007096 0.020878"/>
            <mass value="0.005"/>
            <inertia ixx="0.000002" ixy="0.000000" ixz="0.000000" iyy="0.000002" iyz="0.000000" izz="0.000001"/>
        </inertial>
        <visual>
            <origin xyz="0 0 0" rpy="0 0 0" />
            <geometry>
                <mesh filename="package://cyton_gamma_300_description/meshes/Gripper_Finger1.dae"/>
            </geometry>
                <material name="black"/>
        </visual>
        <collision>
            <origin xyz="0 0 0" rpy="0 0 1.57"/>
            <geometry>
                <mesh filename="package://cyton_gamma_300_description/meshes/Gripper_Finger1.stl"/>
            </geometry>
        </collision>
    </link>

    <!-- Eighth motor located here -->
    <joint name="gripper_joint2" type="prismatic">
        <parent link="wrist_roll" />
        <child link="gripper_finger2" />
        <origin rpy="3.14 0 1.57" xyz="-0.010 0.010 -0.043"/>
        <limit lower="-0.008" upper="0.008" effort="100.0" velocity="1.0" />
        <mimic joint="gripper_joint" multiplier="-1"/>
        <axis xyz="1 0 0" />
    </joint>

    <link name="gripper_finger2">
        <inertial>
            <origin rpy="0 0 0" xyz="0.008938 0.007097 0.020878"/>
            <mass value="0.005"/>
            <inertia ixx="0.000002" ixy="0.000000" ixz="0.000000" iyy="0.000002" iyz="0.000000" izz="0.000001"/>
        </inertial>
        <visual>
            <origin xyz="0 0 0" rpy="0 0 0" />
            <geometry>
                <mesh filename="package://cyton_gamma_300_description/meshes/Gripper_Finger2.dae"/>
            </geometry>
            <material name="black"/>
        </visual>
        <collision>
            <origin xyz="0 0 0" rpy="0 0 1.57"/>
            <geometry>
                <mesh filename="package://cyton_gamma_300_description/meshes/Gripper_Finger2.stl"/>
            </geometry>
        </collision>
    </link>

    <!-- virtual end-effector -->

    <joint name="virtual_endeffector_joint" type="fixed">
        <parent link="wrist_roll" />
        <child link="virtual_endeffector" />
        <origin xyz="-0.002316 0.0079 0.079425" rpy="0 0 0" />
    </joint>

    <link name="virtual_endeffector">
        <visual>
            <origin xyz="0 0 0" rpy="0 0 0" />
            <geometry>
                <sphere radius="0.002" />
            </geometry>
            <material name="grey"/>
        </visual>
    </link>

    <transmission name="tran1">
    	<type>transmission_interface/SimpleTransmission</type>
    	<joint name="shoulder_roll_joint">
      		<hardwareInterface>EffortJointInterface</hardwareInterface>
    	</joint>
    	<actuator name="motor1">
      		<hardwareInterface>EffortJointInterface</hardwareInterface>
      		<mechanicalReduction>1</mechanicalReduction>
    	</actuator>
  	</transmission>

  	<transmission name="tran2">
    	<type>transmission_interface/SimpleTransmission</type>
    	<joint name="shoulder_pitch_joint">
      		<hardwareInterface>EffortJointInterface</hardwareInterface>
    	</joint>
    	<actuator name="motor2">
      		<hardwareInterface>EffortJointInterface</hardwareInterface>
      		<mechanicalReduction>1</mechanicalReduction>
    	</actuator>
  	</transmission>

  	<transmission name="tran3">
    	<type>transmission_interface/SimpleTransmission</type>
    	<joint name="elbow_roll_joint">
    	  	<hardwareInterface>EffortJointInterface</hardwareInterface>
    	</joint>
    	<actuator name="motor3">
      		<hardwareInterface>EffortJointInterface</hardwareInterface>
      		<mechanicalReduction>1</mechanicalReduction>
    	</actuator>
  	</transmission>

  	<transmission name="tran4">
    	<type>transmission_interface/SimpleTransmission</type>
    	<joint name="elbow_pitch_joint">
      		<hardwareInterface>EffortJointInterface</hardwareInterface>
    	</joint>
    	<actuator name="motor4">
      		<hardwareInterface>EffortJointInterface</hardwareInterface>
      		<mechanicalReduction>1</mechanicalReduction>
    	</actuator>
  	</transmission>

  	<transmission name="tran5">
    	<type>transmission_interface/SimpleTransmission</type>
    	<joint name="elbow_yaw_joint">
      		<hardwareInterface>EffortJointInterface</hardwareInterface>
    	</joint>
    	<actuator name="motor5">
      		<hardwareInterface>EffortJointInterface</hardwareInterface>
      		<mechanicalReduction>1</mechanicalReduction>
    	</actuator>
  	</transmission>

  	<transmission name="tran6">
    	<type>transmission_interface/SimpleTransmission</type>
    	<joint name="wrist_pitch_joint">
      		<hardwareInterface>EffortJointInterface</hardwareInterface>
    	</joint>
    	<actuator name="motor6">
      		<hardwareInterface>EffortJointInterface</hardwareInterface>
      		<mechanicalReduction>1</mechanicalReduction>
    	</actuator>
  	</transmission>

  	<transmission name="tran7">
    	<type>transmission_interface/SimpleTransmission</type>
    	<joint name="wrist_roll_joint">
    	  	<hardwareInterface>EffortJointInterface</hardwareInterface>
    	</joint>
    	<actuator name="motor7">
      		<hardwareInterface>EffortJointInterface</hardwareInterface>
      		<mechanicalReduction>1</mechanicalReduction>
    	</actuator>
  	</transmission>

  	<transmission name="tran8">
    	<type>transmission_interface/SimpleTransmission</type>
    	<joint name="gripper_joint">
      		<hardwareInterface>EffortJointInterface</hardwareInterface>
    	</joint>
    	<actuator name="motor8">
      		<hardwareInterface>EffortJointInterface</hardwareInterface>
      		<mechanicalReduction>1</mechanicalReduction>
    	</actuator>
  	</transmission>
</robot>
